Workbook

Sheet FORMULARIO 
A1: FORMULARIO TINTOMETRICO
A3: SISTEMA TINTOMETRICO | C3: TWIST
A4: FORMULARIO DISPONIBLE PARA: | C4: LATEX EXPERTO
C5: LATEX ACRILICO ANTIHONGOS SIPA
C6: LATEX CK-70 PLUS
A11: FORMATO | C11: GALON
A12: UNIDADES | C12: 1/48 ONZAS
A15: COLORANTE | B15: COSTO $LITRO | C15: COSTO POR ONZA
A16: BC | B16: 3338.9 | C16: =(B16/33.817) -> 98.734364
A17: NE | B17: 2847.8 | C17: =(B17/33.817) -> 84.212083
A18: OC | B18: 2947.1 | C18: =(B18/33.817) -> 87.148476
A19: RO | B19: 4430.6 | C19: =(B19/33.817) -> 131.01694
A20: VI | B20: 3900.8 | C20: =(B20/33.817) -> 115.35027
A21: CA | B21: 1694.2 | C21: =(B21/33.817) -> 50.099063
A22: AV | B22: 4006.7 | C22: =(B22/33.817) -> 118.48183
A23: AO | B23: 4205.4 | C23: =(B23/33.817) -> 124.35757
A24: MA | B24: 6490.2 | C24: =(B24/33.817) -> 191.92122
A25: RJ | B25: 3603.9 | C25: =(B25/33.817) -> 106.57066
A26: AZ | B26: 2029.1 | C26: =(B26/33.817) -> 60.002366
A27: VE | B27: 2100.3 | C27: =(B27/33.817) -> 62.107816
... A29: AT | B29: 11065 | C29: =(B29/33.817) -> 327.20229
B31: Densidad kg/gl | C31: Densidad gr/ml | D31: onza galon | E31: ml galon | F31: ml/100 ml | G31: gr/100 ml
A32: Blanca | C32: =(B32/3.785) -> 0 | D32: 128 | E32: =(D32*3785/128) -> 3785 | F32: =(E32*0.03) -> 113.55 | G32: =(F32*C32) -> 0
A33: Media | C33: =(B33/3.785) -> 0 | D33: 124 | E33: =(D33*3785/128) -> 3666.7188 | F33: =(E33*0.03) -> 110.00156 | G33: =(F33*C33) -> 0
A34: Intensa | C34: =(B34/3.785) -> 0 | D34: 120 | E34: =(D34*3785/128) -> 3548.4375 | F34: =(E34*0.03) -> 106.45312 | G34: =(F34*C34) -> 0
C35: =(B35/3.785) -> 0 | E35: =(D35*3785/128) -> 0 | F35: =(E35*0.03) -> 0 | G35: =(F35*C35) -> 0
BE38: FORMULARIO PARA COLOLAB/ GALON ML
A39: FAMILIA | B39: PRODUCTO | C39: CARTILLA | D39: FORMATO | E39: TOLERANCIA LUZ | F39: PRIMER | G39: COLOR | H39: R | I39: G | J39: B | K39: REVISADO EN AT | L39: RESULTADO DE CMC | M39: VERSION | N39: RESPONSABLE | O39: Observaciones | P39: BASE | Q39: Oz base | R39: gr/100 ml | S39: COL_1 | T39: Y | U39: R | V39: 1/48 onzas | W39: Total Onzas galon | X39: ml galon | Y39: ml 100 ml | Z39: COSTO | AA39: COL_2 | AB39: Y | AC39: R | AD39: 1/48 onzas | AE39: Total Onzas galon | AF39: ml galon | AG39: ml 100 ml | AH39: COSTO | AI39: COL_3 | AJ39: Y | AK39: R | AL39: 1/48 onzas | AM39: Total Onzas galon | AN39: ml galon | AO39: ml 100 ml | AP39: COSTO | AQ39: COL_4 | AR39: Y | AS39: R | AT39: 1/48 onzas | AU39: Total Onzas galon | AV39: ml galon | AW39: ml 100 ml | AX39: COSTO | AY39: COSTO TOTAL COLORANTES | AZ39: ONZAS TOTAL COLORANTE | BA39: OZ TOTAL BASE + COLORANTES | BB39: Sobrellenado | BC39: concentrados repetidos | BE39: AO | BF39: AT | BG39: AV | BH39: AZ | BI39: BC | BJ39: CA | BK39: MA | BL39: NE | BM39: OC | BN39: RJ | BO39: RO | BP39: RT | BQ39: VE | BR39: VI
A40: Latex | B40: Latex Experto y Homologos | C40: L. Experto | D40: Galon | E40: - | F40: - | G40: Marfil | P40: Blanca | Q40: 128 | R40: =IF(P40=$A$32,$G$32,IF(P40=$A$33,$G$33,IF(P40=$A$34,$G$34,IF(P40=$A$35,$G$35)))) -> 0 | S40: CA | U40: 0.5 | V40: =(T40*48)+(U40) -> 0.5 | W40: =(V40/48) -> 0.010416667 | X40: =(W40/0.033814) -> 0.30805781 | Y40: =(X40*0.03) -> 0.0092417342 | Z40: =IF(S40="",0,VLOOKUP(S40,[1]!Costo_Twist,2,FALSE)*W40) -> 0.70680673 | AA40: RO | AC40: 0.5 | AD40: =(AB40*48)+(AC40) -> 0.5 | AE40: =(AD40/48) -> 0.010416667 | AF40: =(AE40/0.033814) -> 0.30805781 | AG40: =(AF40*0.03) -> 0.0092417342 | AH40: =IF(AA40="",0,VLOOKUP(AA40,[1]!Costo_Twist,2,FALSE)*AE40) -> 2.611199 | AI40: AV | AK40: 7 | AL40: =(AJ40*48)+(AK40) -> 7 | AM40: =(AL40/48) -> 0.14583333 | AN40: =(AM40/0.033814) -> 4.3128093 | AO40: =(AN40*0.03) -> 0.12938428 | AP40: =IF(AI40="",0,VLOOKUP(AI40,[1]!Costo_Twist,2,FALSE)*AM40) -> 26.819672 | AT40: =(AR40*48)+(AS40) -> 0 | AU40: =(AT40/48) -> 0 | AV40: =(AU40/0.033814) -> 0 | AW40: =(AV40*0.03) -> 0 | AX40: =IF(AQ40="",0,VLOOKUP(AQ40,[1]!Costo_Twist,2,FALSE)*AU40) -> 0 | AY40: =(Z40+AH40+AP40+AX40) -> 30.137677 | AZ40: =(W40+AE40+AM40+AU40) -> 0.16666667 | BA40: =(Q40+AZ40) -> 128.16667 | BB40: =IF(BA40>=133,"sobrellenado","ok") -> ok | BC40: =IF((COUNTIF($AA40,$S40)+COUNTIF($AI40,$S40)+COUNTIF($AQ40,$S40)+COUNTIF($S40,$AA40)+COUNTIF($AI40,$AA40)+COUNTIF($AQ40,$AA40)+COUNTIF($S40,$AI40)+COUNTIF($AA40,$AI40)+COUNTIF($AQ40,$AI40)+COUNTIF($S40,$AQ40)+COUNTIF($AA40,$AQ40)+COUNTIF($AI40,$AQ40))>1,"Falla","ok") -> ok | BE40: =IF(S40=$BE$39,X40,IF(AA40=$BE$39,AF40,IF(AI40=$BE$39,AN40,IF(AQ40=$BE$39,AV40)))) -> FALSE | BF40: =IF(S40=$BF$39,X40,IF(AA40=$BF$39,AF40,IF(AI40=$BF$39,AN40,IF(AQ40=$BF$39,AV40)))) -> FALSE | BG40: =IF(S40=$BG$39,X40,IF(AA40=$BG$39,AF40,IF(AI40=$BG$39,AN40,IF(AQ40=$BG$39,AV40)))) -> 4.3128093 | BH40: =IF(S40=$BH$39,X40,IF(AA40=$BH$39,AF40,IF(AI40=$BH$39,AN40,IF(AQ40=$BH$39,AV40)))) -> FALSE | BI40: =IF(S40=$BI$39,X40,IF(AA40=$BI$39,AF40,IF(AI40=$BI$39,AN40,IF(AQ40=$BI$39,AV40)))) -> FALSE | BJ40: =IF(S40=$BJ$39,X40,IF(AA40=$BJ$39,AF40,IF(AI40=$BJ$39,AN40,IF(AQ40=$BJ$39,AV40)))) -> 0.30805781 | BK40: =IF(S40=$BK$39,X40,IF(AA40=$BK$39,AF40,IF(AI40=$BK$39,AN40,IF(AQ40=$BK$39,AV40)))) -> FALSE | BL40: =IF(S40=$BL$39,X40,IF(AA40=$BL$39,AF40,IF(AI40=$BL$39,AN40,IF(AQ40=$BL$39,AV40)))) -> FALSE | BM40: =IF(S40=$BM$39,X40,IF(AA40=$BM$39,AF40,IF(AI40=$BM$39,AN40,IF(AQ40=$BM$39,AV40)))) -> FALSE | BN40: =IF(S40=$BN$39,X40,IF(AA40=$BN$39,AF40,IF(AI40=$BN$39,AN40,IF(AQ40=$BN$39,AV40)))) -> FALSE | BO40: =IF(S40=$BO$39,X40,IF(AA40=$BO$39,AF40,IF(AI40=$BO$39,AN40,IF(AQ40=$BO$39,AV40)))) -> 0.30805781 | BP40: =IF(S40=$BP$39,X40,IF(AA40=$BP$39,AF40,IF(AI40=$BP$39,AN40,IF(AQ40=$BP$39,AV40)))) -> FALSE | BQ40: =IF(S40=$BQ$39,X40,IF(AA40=$BQ$39,AF40,IF(AI40=$BQ$39,AN40,IF(AQ40=$BQ$39,AV40)))) -> FALSE | BR40: =IF(S40=$BR$39,X40,IF(AA40=$BR$39,AF40,IF(AI40=$BR$39,AN40,IF(AQ40=$BR$39,AV40)))) -> FALSE
A41: Latex | B41: Latex Experto y Homologos | C41: L. Experto | D41: Galon | E41: - | F41: - | G41: Blanco Ingles | H41: 246 | I41: 240 | J41: 228 | P41: Blanca | Q41: 128 | R41: =IF(P41=$A$32,$G$32,IF(P41=$A$33,$G$33,IF(P41=$A$34,$G$34,IF(P41=$A$35,$G$35)))) -> 0 | S41: NE | U41: 2.5 | V41: =(T41*48)+(U41) -> 2.5 | W41: =(V41/48) -> 0.052083333 | X41: =(W41/0.033814) -> 1.540289 | Y41: =(X41*0.03) -> 0.046208671 | Z41: =IF(S41="",0,VLOOKUP(S41,[1]!Costo_Twist,2,FALSE)*W41) -> 6.4669767 | AA41: RO | AC41: 0.5 | AD41: =(AB41*48)+(AC41) -> 0.5 | AE41: =(AD41/48) -> 0.010416667 | AF41: =(AE41/0.033814) -> 0.30805781 | AG41: =(AF41*0.03) -> 0.0092417342 | AH41: =IF(AA41="",0,VLOOKUP(AA41,[1]!Costo_Twist,2,FALSE)*AE41) -> 2.611199 | AI41: AV | AK41: 4.5 | AL41: =(AJ41*48)+(AK41) -> 4.5 | AM41: =(AL41/48) -> 0.09375 | AN41: =(AM41/0.033814) -> 2.7725203 | AO41: =(AN41*0.03) -> 0.083175608 | AP41: =IF(AI41="",0,VLOOKUP(AI41,[1]!Costo_Twist,2,FALSE)*AM41) -> 17.241217 | AT41: =(AR41*48)+(AS41) -> 0 | AU41: =(AT41/48) -> 0 | AV41: =(AU41/0.033814) -> 0 | AW41: =(AV41*0.03) -> 0 | AX41: =IF(AQ41="",0,VLOOKUP(AQ41,[1]!Costo_Twist,2,FALSE)*AU41) -> 0 | AY41: =(Z41+AH41+AP41+AX41) -> 26.319393 | AZ41: =(W41+AE41+AM41+AU41) -> 0.15625 | BA41: =(Q41+AZ41) -> 128.15625 | BB41: =IF(BA41>=133,"sobrellenado","ok") -> ok | BC41: =IF((COUNTIF($AA41,$S41)+COUNTIF($AI41,$S41)+COUNTIF($AQ41,$S41)+COUNTIF($S41,$AA41)+COUNTIF($AI41,$AA41)+COUNTIF($AQ41,$AA41)+COUNTIF($S41,$AI41)+COUNTIF($AA41,$AI41)+COUNTIF($AQ41,$AI41)+COUNTIF($S41,$AQ41)+COUNTIF($AA41,$AQ41)+COUNTIF($AI41,$AQ41))>1,"Falla","ok") -> ok | BE41: =IF(S41=$BE$39,X41,IF(AA41=$BE$39,AF41,IF(AI41=$BE$39,AN41,IF(AQ41=$BE$39,AV41)))) -> FALSE | BF41: =IF(S41=$BF$39,X41,IF(AA41=$BF$39,AF41,IF(AI41=$BF$39,AN41,IF(AQ41=$BF$39,AV41)))) -> FALSE | BG41: =IF(S41=$BG$39,X41,IF(AA41=$BG$39,AF41,IF(AI41=$BG$39,AN41,IF(AQ41=$BG$39,AV41)))) -> 2.7725203 | BH41: =IF(S41=$BH$39,X41,IF(AA41=$BH$39,AF41,IF(AI41=$BH$39,AN41,IF(AQ41=$BH$39,AV41)))) -> FALSE | BI41: =IF(S41=$BI$39,X41,IF(AA41=$BI$39,AF41,IF(AI41=$BI$39,AN41,IF(AQ41=$BI$39,AV41)))) -> FALSE | BJ41: =IF(S41=$BJ$39,X41,IF(AA41=$BJ$39,AF41,IF(AI41=$BJ$39,AN41,IF(AQ41=$BJ$39,AV41)))) -> FALSE | BK41: =IF(S41=$BK$39,X41,IF(AA41=$BK$39,AF41,IF(AI41=$BK$39,AN41,IF(AQ41=$BK$39,AV41)))) -> FALSE | BL41: =IF(S41=$BL$39,X41,IF(AA41=$BL$39,AF41,IF(AI41=$BL$39,AN41,IF(AQ41=$BL$39,AV41)))) -> 1.540289 | BM41: =IF(S41=$BM$39,X41,IF(AA41=$BM$39,AF41,IF(AI41=$BM$39,AN41,IF(AQ41=$BM$39,AV41)))) -> FALSE | BN41: =IF(S41=$BN$39,X41,IF(AA41=$BN$39,AF41,IF(AI41=$BN$39,AN41,IF(AQ41=$BN$39,AV41)))) -> FALSE | BO41: =IF(S41=$BO$39,X41,IF(AA41=$BO$39,AF41,IF(AI41=$BO$39,AN41,IF(AQ41=$BO$39,AV41)))) -> 0.30805781 | BP41: =IF(S41=$BP$39,X41,IF(AA41=$BP$39,AF41,IF(AI41=$BP$39,AN41,IF(AQ41=$BP$39,AV41)))) -> FALSE | BQ41: =IF(S41=$BQ$39,X41,IF(AA41=$BQ$39,AF41,IF(AI41=$BQ$39,AN41,IF(AQ41=$BQ$39,AV41)))) -> FALSE | BR41: =IF(S41=$BR$39,X41,IF(AA41=$BR$39,AF41,IF(AI41=$BR$39,AN41,IF(AQ41=$BR$39,AV41)))) -> FALSE
A42: Latex | B42: Latex Experto y Homologos | C42: L. Experto | D42: Galon | E42: - | F42: - | G42: Damasco | H42: 252 | I42: 220 | J42: 179 | P42: Blanca | Q42: 128 | R42: =IF(P42=$A$32,$G$32,IF(P42=$A$33,$G$33,IF(P42=$A$34,$G$34,IF(P42=$A$35,$G$35)))) -> 0 | S42: CA | U42: 3 | V42: =(T42*48)+(U42) -> 3 | W42: =(V42/48) -> 0.0625 | X42: =(W42/0.033814) -> 1.8483468 | Y42: =(X42*0.03) -> 0.055450405 | Z42: =IF(S42="",0,VLOOKUP(S42,[1]!Costo_Twist,2,FALSE)*W42) -> 4.2408404 | AA42: RO | AC42: 3.5 | AD42: =(AB42*48)+(AC42) -> 3.5 | AE42: =(AD42/48) -> 0.072916667 | AF42: =(AE42/0.033814) -> 2.1564046 | AG42: =(AF42*0.03) -> 0.064692139 | AH42: =IF(AA42="",0,VLOOKUP(AA42,[1]!Costo_Twist,2,FALSE)*AE42) -> 18.278393 | AI42: OC | AK42: 30 | AL42: =(AJ42*48)+(AK42) -> 30 | AM42: =(AL42/48) -> 0.625 | AN42: =(AM42/0.033814) -> 18.483468 | AO42: =(AN42*0.03) -> 0.55450405 | AP42: =IF(AI42="",0,VLOOKUP(AI42,[1]!Costo_Twist,2,FALSE)*AM42) -> 91.513884 | AT42: =(AR42*48)+(AS42) -> 0 | AU42: =(AT42/48) -> 0 | AV42: =(AU42/0.033814) -> 0 | AW42: =(AV42*0.03) -> 0 | AX42: =IF(AQ42="",0,VLOOKUP(AQ42,[1]!Costo_Twist,2,FALSE)*AU42) -> 0 | AY42: =(Z42+AH42+AP42+AX42) -> 114.03312 | AZ42: =(W42+AE42+AM42+AU42) -> 0.76041667 | BA42: =(Q42+AZ42) -> 128.76042 | BB42: =IF(BA42>=133,"sobrellenado","ok") -> ok | BC42: =IF((COUNTIF($AA42,$S42)+COUNTIF($AI42,$S42)+COUNTIF($AQ42,$S42)+COUNTIF($S42,$AA42)+COUNTIF($AI42,$AA42)+COUNTIF($AQ42,$AA42)+COUNTIF($S42,$AI42)+COUNTIF($AA42,$AI42)+COUNTIF($AQ42,$AI42)+COUNTIF($S42,$AQ42)+COUNTIF($AA42,$AQ42)+COUNTIF($AI42,$AQ42))>1,"Falla","ok") -> ok | BE42: =IF(S42=$BE$39,X42,IF(AA42=$BE$39,AF42,IF(AI42=$BE$39,AN42,IF(AQ42=$BE$39,AV42)))) -> FALSE | BF42: =IF(S42=$BF$39,X42,IF(AA42=$BF$39,AF42,IF(AI42=$BF$39,AN42,IF(AQ42=$BF$39,AV42)))) -> FALSE | BG42: =IF(S42=$BG$39,X42,IF(AA42=$BG$39,AF42,IF(AI42=$BG$39,AN42,IF(AQ42=$BG$39,AV42)))) -> FALSE | BH42: =IF(S42=$BH$39,X42,IF(AA42=$BH$39,AF42,IF(AI42=$BH$39,AN42,IF(AQ42=$BH$39,AV42)))) -> FALSE | BI42: =IF(S42=$BI$39,X42,IF(AA42=$BI$39,AF42,IF(AI42=$BI$39,AN42,IF(AQ42=$BI$39,AV42)))) -> FALSE | BJ42: =IF(S42=$BJ$39,X42,IF(AA42=$BJ$39,AF42,IF(AI42=$BJ$39,AN42,IF(AQ42=$BJ$39,AV42)))) -> 1.8483468 | BK42: =IF(S42=$BK$39,X42,IF(AA42=$BK$39,AF42,IF(AI42=$BK$39,AN42,IF(AQ42=$BK$39,AV42)))) -> FALSE | BL42: =IF(S42=$BL$39,X42,IF(AA42=$BL$39,AF42,IF(AI42=$BL$39,AN42,IF(AQ42=$BL$39,AV42)))) -> FALSE | BM42: =IF(S42=$BM$39,X42,IF(AA42=$BM$39,AF42,IF(AI42=$BM$39,AN42,IF(AQ42=$BM$39,AV42)))) -> 18.483468 | BN42: =IF(S42=$BN$39,X42,IF(AA42=$BN$39,AF42,IF(AI42=$BN$39,AN42,IF(AQ42=$BN$39,AV42)))) -> FALSE | BO42: =IF(S42=$BO$39,X42,IF(AA42=$BO$39,AF42,IF(AI42=$BO$39,AN42,IF(AQ42=$BO$39,AV42)))) -> 2.1564046 | BP42: =IF(S42=$BP$39,X42,IF(AA42=$BP$39,AF42,IF(AI42=$BP$39,AN42,IF(AQ42=$BP$39,AV42)))) -> FALSE | BQ42: =IF(S42=$BQ$39,X42,IF(AA42=$BQ$39,AF42,IF(AI42=$BQ$39,AN42,IF(AQ42=$BQ$39,AV42)))) -> FALSE | BR42: =IF(S42=$BR$39,X42,IF(AA42=$BR$39,AF42,IF(AI42=$BR$39,AN42,IF(AQ42=$BR$39,AV42)))) -> FALSE
A43: Latex | B43: Latex Experto y Homologos | C43: L. Experto | D43: Galon | E43: - | F43: - | G43: Ocre | H43: 254 | I43: 219 | J43: 137 | P43: Media | Q43: 124 | R43: =IF(P43=$A$32,$G$32,IF(P43=$A$33,$G$33,IF(P43=$A$34,$G$34,IF(P43=$A$35,$G$35)))) -> 0 | S43: AV | U43: 119 | V43: =(T43*48)+(U43) -> 119 | W43: =(V43/48) -> 2.4791667 | X43: =(W43/0.033814) -> 73.317758 | Y43: =(X43*0.03) -> 2.1995327 | Z43: =IF(S43="",0,VLOOKUP(S43,[1]!Costo_Twist,2,FALSE)*W43) -> 455.93442 | AA43: OC | AC43: 86.5 | AD43: =(AB43*48)+(AC43) -> 86.5 | AE43: =(AD43/48) -> 1.8020833 | AF43: =(AE43/0.033814) -> 53.294001 | AG43: =(AF43*0.03) -> 1.59882 | AH43: =IF(AA43="",0,VLOOKUP(AA43,[1]!Costo_Twist,2,FALSE)*AE43) -> 263.86503 | AI43: RJ | AK43: 2 | AL43: =(AJ43*48)+(AK43) -> 2 | AM43: =(AL43/48) -> 0.041666667 | AN43: =(AM43/0.033814) -> 1.2322312 | AO43: =(AN43*0.03) -> 0.036966937 | AP43: =IF(AI43="",0,VLOOKUP(AI43,[1]!Costo_Twist,2,FALSE)*AM43) -> 8.5000887 | AT43: =(AR43*48)+(AS43) -> 0 | AU43: =(AT43/48) -> 0 | AV43: =(AU43/0.033814) -> 0 | AW43: =(AV43*0.03) -> 0 | AX43: =IF(AQ43="",0,VLOOKUP(AQ43,[1]!Costo_Twist,2,FALSE)*AU43) -> 0 | AY43: =(Z43+AH43+AP43+AX43) -> 728.29954 | AZ43: =(W43+AE43+AM43+AU43) -> 4.3229167 | BA43: =(Q43+AZ43) -> 128.32292 | BB43: =IF(BA43>=133,"sobrellenado","ok") -> ok | BC43: =IF((COUNTIF($AA43,$S43)+COUNTIF($AI43,$S43)+COUNTIF($AQ43,$S43)+COUNTIF($S43,$AA43)+COUNTIF($AI43,$AA43)+COUNTIF($AQ43,$AA43)+COUNTIF($S43,$AI43)+COUNTIF($AA43,$AI43)+COUNTIF($AQ43,$AI43)+COUNTIF($S43,$AQ43)+COUNTIF($AA43,$AQ43)+COUNTIF($AI43,$AQ43))>1,"Falla","ok") -> ok | BE43: =IF(S43=$BE$39,X43,IF(AA43=$BE$39,AF43,IF(AI43=$BE$39,AN43,IF(AQ43=$BE$39,AV43)))) -> FALSE | BF43: =IF(S43=$BF$39,X43,IF(AA43=$BF$39,AF43,IF(AI43=$BF$39,AN43,IF(AQ43=$BF$39,AV43)))) -> FALSE | BG43: =IF(S43=$BG$39,X43,IF(AA43=$BG$39,AF43,IF(AI43=$BG$39,AN43,IF(AQ43=$BG$39,AV43)))) -> 73.317758 | BH43: =IF(S43=$BH$39,X43,IF(AA43=$BH$39,AF43,IF(AI43=$BH$39,AN43,IF(AQ43=$BH$39,AV43)))) -> FALSE | BI43: =IF(S43=$BI$39,X43,IF(AA43=$BI$39,AF43,IF(AI43=$BI$39,AN43,IF(AQ43=$BI$39,AV43)))) -> FALSE | BJ43: =IF(S43=$BJ$39,X43,IF(AA43=$BJ$39,AF43,IF(AI43=$BJ$39,AN43,IF(AQ43=$BJ$39,AV43)))) -> FALSE | BK43: =IF(S43=$BK$39,X43,IF(AA43=$BK$39,AF43,IF(AI43=$BK$39,AN43,IF(AQ43=$BK$39,AV43)))) -> FALSE | BL43: =IF(S43=$BL$39,X43,IF(AA43=$BL$39,AF43,IF(AI43=$BL$39,AN43,IF(AQ43=$BL$39,AV43)))) -> FALSE | BM43: =IF(S43=$BM$39,X43,IF(AA43=$BM$39,AF43,IF(AI43=$BM$39,AN43,IF(AQ43=$BM$39,AV43)))) -> 53.294001 | BN43: =IF(S43=$BN$39,X43,IF(AA43=$BN$39,AF43,IF(AI43=$BN$39,AN43,IF(AQ43=$BN$39,AV43)))) -> 1.2322312 | BO43: =IF(S43=$BO$39,X43,IF(AA43=$BO$39,AF43,IF(AI43=$BO$39,AN43,IF(AQ43=$BO$39,AV43)))) -> FALSE | BP43: =IF(S43=$BP$39,X43,IF(AA43=$BP$39,AF43,IF(AI43=$BP$39,AN43,IF(AQ43=$BP$39,AV43)))) -> FALSE | BQ43: =IF(S43=$BQ$39,X43,IF(AA43=$BQ$39,AF43,IF(AI43=$BQ$39,AN43,IF(AQ43=$BQ$39,AV43)))) -> FALSE | BR43: =IF(S43=$BR$39,X43,IF(AA43=$BR$39,AF43,IF(AI43=$BR$39,AN43,IF(AQ43=$BR$39,AV43)))) -> FALSE
A44: Latex | B44: Latex Experto y Homologos | C44: L. Experto | D44: Galon | E44: - | F44: - | G44: Crema | H44: 248 | I44: 233 | J44: 192 | P44: Blanca | Q44: 128 | R44: =IF(P44=$A$32,$G$32,IF(P44=$A$33,$G$33,IF(P44=$A$34,$G$34,IF(P44=$A$35,$G$35)))) -> 0 | S44: OC | U44: 32.5 | V44: =(T44*48)+(U44) -> 32.5 | W44: =(V44/48) -> 0.67708333 | X44: =(W44/0.033814) -> 20.023757 | Y44: =(X44*0.03) -> 0.60071272 | Z44: =IF(S44="",0,VLOOKUP(S44,[1]!Costo_Twist,2,FALSE)*W44) -> 99.140041 | AA44: NE | AC44: 2 | AD44: =(AB44*48)+(AC44) -> 2 | AE44: =(AD44/48) -> 0.041666667 | AF44: =(AE44/0.033814) -> 1.2322312 | AG44: =(AF44*0.03) -> 0.036966937 | AH44: =IF(AA44="",0,VLOOKUP(AA44,[1]!Costo_Twist,2,FALSE)*AE44) -> 5.1735813 | AI44: RJ | AK44: 1.5 | AL44: =(AJ44*48)+(AK44) -> 1.5 | AM44: =(AL44/48) -> 0.03125 | AN44: =(AM44/0.033814) -> 0.92417342 | AO44: =(AN44*0.03) -> 0.027725203 | AP44: =IF(AI44="",0,VLOOKUP(AI44,[1]!Costo_Twist,2,FALSE)*AM44) -> 6.3750665 | AT44: =(AR44*48)+(AS44) -> 0 | AU44: =(AT44/48) -> 0 | AV44: =(AU44/0.033814) -> 0 | AW44: =(AV44*0.03) -> 0 | AX44: =IF(AQ44="",0,VLOOKUP(AQ44,[1]!Costo_Twist,2,FALSE)*AU44) -> 0 | AY44: =(Z44+AH44+AP44+AX44) -> 110.68869 | AZ44: =(W44+AE44+AM44+AU44) -> 0.75 | BA44: =(Q44+AZ44) -> 128.75 | BB44: =IF(BA44>=133,"sobrellenado","ok") -> ok | BC44: =IF((COUNTIF($AA44,$S44)+COUNTIF($AI44,$S44)+COUNTIF($AQ44,$S44)+COUNTIF($S44,$AA44)+COUNTIF($AI44,$AA44)+COUNTIF($AQ44,$AA44)+COUNTIF($S44,$AI44)+COUNTIF($AA44,$AI44)+COUNTIF($AQ44,$AI44)+COUNTIF($S44,$AQ44)+COUNTIF($AA44,$AQ44)+COUNTIF($AI44,$AQ44))>1,"Falla","ok") -> ok | BE44: =IF(S44=$BE$39,X44,IF(AA44=$BE$39,AF44,IF(AI44=$BE$39,AN44,IF(AQ44=$BE$39,AV44)))) -> FALSE | BF44: =IF(S44=$BF$39,X44,IF(AA44=$BF$39,AF44,IF(AI44=$BF$39,AN44,IF(AQ44=$BF$39,AV44)))) -> FALSE | BG44: =IF(S44=$BG$39,X44,IF(AA44=$BG$39,AF44,IF(AI44=$BG$39,AN44,IF(AQ44=$BG$39,AV44)))) -> FALSE | BH44: =IF(S44=$BH$39,X44,IF(AA44=$BH$39,AF44,IF(AI44=$BH$39,AN44,IF(AQ44=$BH$39,AV44)))) -> FALSE | BI44: =IF(S44=$BI$39,X44,IF(AA44=$BI$39,AF44,IF(AI44=$BI$39,AN44,IF(AQ44=$BI$39,AV44)))) -> FALSE | BJ44: =IF(S44=$BJ$39,X44,IF(AA44=$BJ$39,AF44,IF(AI44=$BJ$39,AN44,IF(AQ44=$BJ$39,AV44)))) -> FALSE | BK44: =IF(S44=$BK$39,X44,IF(AA44=$BK$39,AF44,IF(AI44=$BK$39,AN44,IF(AQ44=$BK$39,AV44)))) -> FALSE | BL44: =IF(S44=$BL$39,X44,IF(AA44=$BL$39,AF44,IF(AI44=$BL$39,AN44,IF(AQ44=$BL$39,AV44)))) -> 1.2322312 | BM44: =IF(S44=$BM$39,X44,IF(AA44=$BM$39,AF44,IF(AI44=$BM$39,AN44,IF(AQ44=$BM$39,AV44)))) -> 20.023757 | BN44: =IF(S44=$BN$39,X44,IF(AA44=$BN$39,AF44,IF(AI44=$BN$39,AN44,IF(AQ44=$BN$39,AV44)))) -> 0.92417342 | BO44: =IF(S44=$BO$39,X44,IF(AA44=$BO$39,AF44,IF(AI44=$BO$39,AN44,IF(AQ44=$BO$39,AV44)))) -> FALSE | BP44: =IF(S44=$BP$39,X44,IF(AA44=$BP$39,AF44,IF(AI44=$BP$39,AN44,IF(AQ44=$BP$39,AV44)))) -> FALSE | BQ44: =IF(S44=$BQ$39,X44,IF(AA44=$BQ$39,AF44,IF(AI44=$BQ$39,AN44,IF(AQ44=$BQ$39,AV44)))) -> FALSE | BR44: =IF(S44=$BR$39,X44,IF(AA44=$BR$39,AF44,IF(AI44=$BR$39,AN44,IF(AQ44=$BR$39,AV44)))) -> FALSE
A45: Latex | B45: Latex Experto y Homologos | C45: L. Experto | D45: Galon | E45: - | F45: - | G45: Celeste Cielo | H45: 198 | I45: 230 | J45: 245 | P45: Blanca | Q45: 128 | R45: =IF(P45=$A$32,$G$32,IF(P45=$A$33,$G$33,IF(P45=$A$34,$G$34,IF(P45=$A$35,$G$35)))) -> 0 | S45: NE | U45: 1 | V45: =(T45*48)+(U45) -> 1 | W45: =(V45/48) -> 0.020833333 | X45: =(W45/0.033814) -> 0.61611561 | Y45: =(X45*0.03) -> 0.018483468 | Z45: =IF(S45="",0,VLOOKUP(S45,[1]!Costo_Twist,2,FALSE)*W45) -> 2.5867907 | AA45: AZ | AC45: 8 | AD45: =(AB45*48)+(AC45) -> 8 | AE45: =(AD45/48) -> 0.16666667 | AF45: =(AE45/0.033814) -> 4.9289249 | AG45: =(AF45*0.03) -> 0.14786775 | AH45: =IF(AA45="",0,VLOOKUP(AA45,[1]!Costo_Twist,2,FALSE)*AE45) -> 21.819696 | AI45: CA | AK45: 0.5 | AL45: =(AJ45*48)+(AK45) -> 0.5 | AM45: =(AL45/48) -> 0.010416667 | AN45: =(AM45/0.033814) -> 0.30805781 | AO45: =(AN45*0.03) -> 0.0092417342 | AP45: =IF(AI45="",0,VLOOKUP(AI45,[1]!Costo_Twist,2,FALSE)*AM45) -> 0.70680673 | AT45: =(AR45*48)+(AS45) -> 0 | AU45: =(AT45/48) -> 0 | AV45: =(AU45/0.033814) -> 0 | AW45: =(AV45*0.03) -> 0 | AX45: =IF(AQ45="",0,VLOOKUP(AQ45,[1]!Costo_Twist,2,FALSE)*AU45) -> 0 | AY45: =(Z45+AH45+AP45+AX45) -> 25.113294 | AZ45: =(W45+AE45+AM45+AU45) -> 0.19791667 | BA45: =(Q45+AZ45) -> 128.19792 | BB45: =IF(BA45>=133,"sobrellenado","ok") -> ok | BC45: =IF((COUNTIF($AA45,$S45)+COUNTIF($AI45,$S45)+COUNTIF($AQ45,$S45)+COUNTIF($S45,$AA45)+COUNTIF($AI45,$AA45)+COUNTIF($AQ45,$AA45)+COUNTIF($S45,$AI45)+COUNTIF($AA45,$AI45)+COUNTIF($AQ45,$AI45)+COUNTIF($S45,$AQ45)+COUNTIF($AA45,$AQ45)+COUNTIF($AI45,$AQ45))>1,"Falla","ok") -> ok | BE45: =IF(S45=$BE$39,X45,IF(AA45=$BE$39,AF45,IF(AI45=$BE$39,AN45,IF(AQ45=$BE$39,AV45)))) -> FALSE | BF45: =IF(S45=$BF$39,X45,IF(AA45=$BF$39,AF45,IF(AI45=$BF$39,AN45,IF(AQ45=$BF$39,AV45)))) -> FALSE | BG45: =IF(S45=$BG$39,X45,IF(AA45=$BG$39,AF45,IF(AI45=$BG$39,AN45,IF(AQ45=$BG$39,AV45)))) -> FALSE | BH45: =IF(S45=$BH$39,X45,IF(AA45=$BH$39,AF45,IF(AI45=$BH$39,AN45,IF(AQ45=$BH$39,AV45)))) -> 4.9289249 | BI45: =IF(S45=$BI$39,X45,IF(AA45=$BI$39,AF45,IF(AI45=$BI$39,AN45,IF(AQ45=$BI$39,AV45)))) -> FALSE | BJ45: =IF(S45=$BJ$39,X45,IF(AA45=$BJ$39,AF45,IF(AI45=$BJ$39,AN45,IF(AQ45=$BJ$39,AV45)))) -> 0.30805781 | BK45: =IF(S45=$BK$39,X45,IF(AA45=$BK$39,AF45,IF(AI45=$BK$39,AN45,IF(AQ45=$BK$39,AV45)))) -> FALSE | BL45: =IF(S45=$BL$39,X45,IF(AA45=$BL$39,AF45,IF(AI45=$BL$39,AN45,IF(AQ45=$BL$39,AV45)))) -> 0.61611561 | BM45: =IF(S45=$BM$39,X45,IF(AA45=$BM$39,AF45,IF(AI45=$BM$39,AN45,IF(AQ45=$BM$39,AV45)))) -> FALSE | BN45: =IF(S45=$BN$39,X45,IF(AA45=$BN$39,AF45,IF(AI45=$BN$39,AN45,IF(AQ45=$BN$39,AV45)))) -> FALSE | BO45: =IF(S45=$BO$39,X45,IF(AA45=$BO$39,AF45,IF(AI45=$BO$39,AN45,IF(AQ45=$BO$39,AV45)))) -> FALSE | BP45: =IF(S45=$BP$39,X45,IF(AA45=$BP$39,AF45,IF(AI45=$BP$39,AN45,IF(AQ45=$BP$39,AV45)))) -> FALSE | BQ45: =IF(S45=$BQ$39,X45,IF(AA45=$BQ$39,AF45,IF(AI45=$BQ$39,AN45,IF(AQ45=$BQ$39,AV45)))) -> FALSE | BR45: =IF(S45=$BR$39,X45,IF(AA45=$BR$39,AF45,IF(AI45=$BR$39,AN45,IF(AQ45=$BR$39,AV45)))) -> FALSE
A46: Latex | B46: Latex Experto y Homologos | C46: L. Experto | D46: Galon | E46: - | F46: - | G46: Blanco Invierno | H46: 239 | I46: 242 | J46: 235 | P46: Blanca | Q46: 128 | R46: =IF(P46=$A$32,$G$32,IF(P46=$A$33,$G$33,IF(P46=$A$34,$G$34,IF(P46=$A$35,$G$35)))) -> 0 | S46: NE | U46: 3 | V46: =(T46*48)+(U46) -> 3 | W46: =(V46/48) -> 0.0625 | X46: =(W46/0.033814) -> 1.8483468 | Y46: =(X46*0.03) -> 0.055450405 | Z46: =IF(S46="",0,VLOOKUP(S46,[1]!Costo_Twist,2,FALSE)*W46) -> 7.760372 | AA46: CA | AC46: 4 | AD46: =(AB46*48)+(AC46) -> 4 | AE46: =(AD46/48) -> 0.083333333 | AF46: =(AE46/0.033814) -> 2.4644625 | AG46: =(AF46*0.03) -> 0.073933874 | AH46: =IF(AA46="",0,VLOOKUP(AA46,[1]!Costo_Twist,2,FALSE)*AE46) -> 5.6544539 | AL46: =(AJ46*48)+(AK46) -> 0 | AM46: =(AL46/48) -> 0 | AN46: =(AM46/0.033814) -> 0 | AO46: =(AN46*0.03) -> 0 | AP46: =IF(AI46="",0,VLOOKUP(AI46,[1]!Costo_Twist,2,FALSE)*AM46) -> 0 | AT46: =(AR46*48)+(AS46) -> 0 | AU46: =(AT46/48) -> 0 | AV46: =(AU46/0.033814) -> 0 | AW46: =(AV46*0.03) -> 0 | AX46: =IF(AQ46="",0,VLOOKUP(AQ46,[1]!Costo_Twist,2,FALSE)*AU46) -> 0 | AY46: =(Z46+AH46+AP46+AX46) -> 13.414826 | AZ46: =(W46+AE46+AM46+AU46) -> 0.14583333 | BA46: =(Q46+AZ46) -> 128.14583 | BB46: =IF(BA46>=133,"sobrellenado","ok") -> ok | BC46: =IF((COUNTIF($AA46,$S46)+COUNTIF($AI46,$S46)+COUNTIF($AQ46,$S46)+COUNTIF($S46,$AA46)+COUNTIF($AI46,$AA46)+COUNTIF($AQ46,$AA46)+COUNTIF($S46,$AI46)+COUNTIF($AA46,$AI46)+COUNTIF($AQ46,$AI46)+COUNTIF($S46,$AQ46)+COUNTIF($AA46,$AQ46)+COUNTIF($AI46,$AQ46))>1,"Falla","ok") -> ok | BE46: =IF(S46=$BE$39,X46,IF(AA46=$BE$39,AF46,IF(AI46=$BE$39,AN46,IF(AQ46=$BE$39,AV46)))) -> FALSE | BF46: =IF(S46=$BF$39,X46,IF(AA46=$BF$39,AF46,IF(AI46=$BF$39,AN46,IF(AQ46=$BF$39,AV46)))) -> FALSE | BG46: =IF(S46=$BG$39,X46,IF(AA46=$BG$39,AF46,IF(AI46=$BG$39,AN46,IF(AQ46=$BG$39,AV46)))) -> FALSE | BH46: =IF(S46=$BH$39,X46,IF(AA46=$BH$39,AF46,IF(AI46=$BH$39,AN46,IF(AQ46=$BH$39,AV46)))) -> FALSE | BI46: =IF(S46=$BI$39,X46,IF(AA46=$BI$39,AF46,IF(AI46=$BI$39,AN46,IF(AQ46=$BI$39,AV46)))) -> FALSE | BJ46: =IF(S46=$BJ$39,X46,IF(AA46=$BJ$39,AF46,IF(AI46=$BJ$39,AN46,IF(AQ46=$BJ$39,AV46)))) -> 2.4644625 | BK46: =IF(S46=$BK$39,X46,IF(AA46=$BK$39,AF46,IF(AI46=$BK$39,AN46,IF(AQ46=$BK$39,AV46)))) -> FALSE | BL46: =IF(S46=$BL$39,X46,IF(AA46=$BL$39,AF46,IF(AI46=$BL$39,AN46,IF(AQ46=$BL$39,AV46)))) -> 1.8483468 | BM46: =IF(S46=$BM$39,X46,IF(AA46=$BM$39,AF46,IF(AI46=$BM$39,AN46,IF(AQ46=$BM$39,AV46)))) -> FALSE | BN46: =IF(S46=$BN$39,X46,IF(AA46=$BN$39,AF46,IF(AI46=$BN$39,AN46,IF(AQ46=$BN$39,AV46)))) -> FALSE | BO46: =IF(S46=$BO$39,X46,IF(AA46=$BO$39,AF46,IF(AI46=$BO$39,AN46,IF(AQ46=$BO$39,AV46)))) -> FALSE | BP46: =IF(S46=$BP$39,X46,IF(AA46=$BP$39,AF46,IF(AI46=$BP$39,AN46,IF(AQ46=$BP$39,AV46)))) -> FALSE | BQ46: =IF(S46=$BQ$39,X46,IF(AA46=$BQ$39,AF46,IF(AI46=$BQ$39,AN46,IF(AQ46=$BQ$39,AV46)))) -> FALSE | BR46: =IF(S46=$BR$39,X46,IF(AA46=$BR$39,AF46,IF(AI46=$BR$39,AN46,IF(AQ46=$BR$39,AV46)))) -> FALSE
A47: Latex | B47: Latex Experto y Homologos | C47: L. Experto | D47: Galon | E47: - | F47: - | G47: Rojo Colonial N | H47: 185 | I47: 79 | J47: 66 | P47: Intensa | Q47: 120 | R47: =IF(P47=$A$32,$G$32,IF(P47=$A$33,$G$33,IF(P47=$A$34,$G$34,IF(P47=$A$35,$G$35)))) -> 0 | S47: RO | U47: 200.5 | V47: =(T47*48)+(U47) -> 200.5 | W47: =(V47/48) -> 4.1770833 | X47: =(W47/0.033814) -> 123.53118 | Y47: =(X47*0.03) -> 3.7059354 | Z47: =IF(S47="",0,VLOOKUP(S47,[1]!Costo_Twist,2,FALSE)*W47) -> 1047.0908 | AA47: MA | AC47: 122.5 | AD47: =(AB47*48)+(AC47) -> 122.5 | AE47: =(AD47/48) -> 2.5520833 | AF47: =(AE47/0.033814) -> 75.474163 | AG47: =(AF47*0.03) -> 2.2642249 | AH47: =IF(AA47="",0,VLOOKUP(AA47,[1]!Costo_Twist,2,FALSE)*AE47) -> 741.38485 | AI47: NE | AK47: 23.5 | AL47: =(AJ47*48)+(AK47) -> 23.5 | AM47: =(AL47/48) -> 0.48958333 | AN47: =(AM47/0.033814) -> 14.478717 | AO47: =(AN47*0.03) -> 0.43436151 | AP47: =IF(AI47="",0,VLOOKUP(AI47,[1]!Costo_Twist,2,FALSE)*AM47) -> 60.789581 | AT47: =(AR47*48)+(AS47) -> 0 | AU47: =(AT47/48) -> 0 | AV47: =(AU47/0.033814) -> 0 | AW47: =(AV47*0.03) -> 0 | AX47: =IF(AQ47="",0,VLOOKUP(AQ47,[1]!Costo_Twist,2,FALSE)*AU47) -> 0 | AY47: =(Z47+AH47+AP47+AX47) -> 1849.2652 | AZ47: =(W47+AE47+AM47+AU47) -> 7.21875 | BA47: =(Q47+AZ47) -> 127.21875 | BB47: =IF(BA47>=133,"sobrellenado","ok") -> ok | BC47: =IF((COUNTIF($AA47,$S47)+COUNTIF($AI47,$S47)+COUNTIF($AQ47,$S47)+COUNTIF($S47,$AA47)+COUNTIF($AI47,$AA47)+COUNTIF($AQ47,$AA47)+COUNTIF($S47,$AI47)+COUNTIF($AA47,$AI47)+COUNTIF($AQ47,$AI47)+COUNTIF($S47,$AQ47)+COUNTIF($AA47,$AQ47)+COUNTIF($AI47,$AQ47))>1,"Falla","ok") -> ok | BE47: =IF(S47=$BE$39,X47,IF(AA47=$BE$39,AF47,IF(AI47=$BE$39,AN47,IF(AQ47=$BE$39,AV47)))) -> FALSE | BF47: =IF(S47=$BF$39,X47,IF(AA47=$BF$39,AF47,IF(AI47=$BF$39,AN47,IF(AQ47=$BF$39,AV47)))) -> FALSE | BG47: =IF(S47=$BG$39,X47,IF(AA47=$BG$39,AF47,IF(AI47=$BG$39,AN47,IF(AQ47=$BG$39,AV47)))) -> FALSE | BH47: =IF(S47=$BH$39,X47,IF(AA47=$BH$39,AF47,IF(AI47=$BH$39,AN47,IF(AQ47=$BH$39,AV47)))) -> FALSE | BI47: =IF(S47=$BI$39,X47,IF(AA47=$BI$39,AF47,IF(AI47=$BI$39,AN47,IF(AQ47=$BI$39,AV47)))) -> FALSE | BJ47: =IF(S47=$BJ$39,X47,IF(AA47=$BJ$39,AF47,IF(AI47=$BJ$39,AN47,IF(AQ47=$BJ$39,AV47)))) -> FALSE | BK47: =IF(S47=$BK$39,X47,IF(AA47=$BK$39,AF47,IF(AI47=$BK$39,AN47,IF(AQ47=$BK$39,AV47)))) -> 75.474163 | BL47: =IF(S47=$BL$39,X47,IF(AA47=$BL$39,AF47,IF(AI47=$BL$39,AN47,IF(AQ47=$BL$39,AV47)))) -> 14.478717 | BM47: =IF(S47=$BM$39,X47,IF(AA47=$BM$39,AF47,IF(AI47=$BM$39,AN47,IF(AQ47=$BM$39,AV47)))) -> FALSE | BN47: =IF(S47=$BN$39,X47,IF(AA47=$BN$39,AF47,IF(AI47=$BN$39,AN47,IF(AQ47=$BN$39,AV47)))) -> FALSE | BO47: =IF(S47=$BO$39,X47,IF(AA47=$BO$39,AF47,IF(AI47=$BO$39,AN47,IF(AQ47=$BO$39,AV47)))) -> 123.53118 | BP47: =IF(S47=$BP$39,X47,IF(AA47=$BP$39,AF47,IF(AI47=$BP$39,AN47,IF(AQ47=$BP$39,AV47)))) -> FALSE | BQ47: =IF(S47=$BQ$39,X47,IF(AA47=$BQ$39,AF47,IF(AI47=$BQ$39,AN47,IF(AQ47=$BQ$39,AV47)))) -> FALSE | BR47: =IF(S47=$BR$39,X47,IF(AA47=$BR$39,AF47,IF(AI47=$BR$39,AN47,IF(AQ47=$BR$39,AV47)))) -> FALSE
A48: Latex | B48: Latex Experto y Homologos | C48: L. Experto | D48: Galon | E48: - | F48: - | G48: Marfil Oriental | H48: 253 | I48: 247 | J48: 225 | P48: Blanca | Q48: 128 | R48: =IF(P48=$A$32,$G$32,IF(P48=$A$33,$G$33,IF(P48=$A$34,$G$34,IF(P48=$A$35,$G$35)))) -> 0 | S48: CA | U48: 0.5 | V48: =(T48*48)+(U48) -> 0.5 | W48: =(V48/48) -> 0.010416667 | X48: =(W48/0.033814) -> 0.30805781 | Y48: =(X48*0.03) -> 0.0092417342 | Z48: =IF(S48="",0,VLOOKUP(S48,[1]!Costo_Twist,2,FALSE)*W48) -> 0.70680673 | AA48: MA | AC48: 0.5 | AD48: =(AB48*48)+(AC48) -> 0.5 | AE48: =(AD48/48) -> 0.010416667 | AF48: =(AE48/0.033814) -> 0.30805781 | AG48: =(AF48*0.03) -> 0.0092417342 | AH48: =IF(AA48="",0,VLOOKUP(AA48,[1]!Costo_Twist,2,FALSE)*AE48) -> 3.0260606 | AI48: OC | AK48: 5 | AL48: =(AJ48*48)+(AK48) -> 5 | AM48: =(AL48/48) -> 0.10416667 | AN48: =(AM48/0.033814) -> 3.0805781 | AO48: =(AN48*0.03) -> 0.092417342 | AP48: =IF(AI48="",0,VLOOKUP(AI48,[1]!Costo_Twist,2,FALSE)*AM48) -> 15.252314 | AT48: =(AR48*48)+(AS48) -> 0 | AU48: =(AT48/48) -> 0 | AV48: =(AU48/0.033814) -> 0 | AW48: =(AV48*0.03) -> 0 | AX48: =IF(AQ48="",0,VLOOKUP(AQ48,[1]!Costo_Twist,2,FALSE)*AU48) -> 0 | AY48: =(Z48+AH48+AP48+AX48) -> 18.985181 | AZ48: =(W48+AE48+AM48+AU48) -> 0.125 | BA48: =(Q48+AZ48) -> 128.125 | BB48: =IF(BA48>=133,"sobrellenado","ok") -> ok | BC48: =IF((COUNTIF($AA48,$S48)+COUNTIF($AI48,$S48)+COUNTIF($AQ48,$S48)+COUNTIF($S48,$AA48)+COUNTIF($AI48,$AA48)+COUNTIF($AQ48,$AA48)+COUNTIF($S48,$AI48)+COUNTIF($AA48,$AI48)+COUNTIF($AQ48,$AI48)+COUNTIF($S48,$AQ48)+COUNTIF($AA48,$AQ48)+COUNTIF($AI48,$AQ48))>1,"Falla","ok") -> ok | BE48: =IF(S48=$BE$39,X48,IF(AA48=$BE$39,AF48,IF(AI48=$BE$39,AN48,IF(AQ48=$BE$39,AV48)))) -> FALSE | BF48: =IF(S48=$BF$39,X48,IF(AA48=$BF$39,AF48,IF(AI48=$BF$39,AN48,IF(AQ48=$BF$39,AV48)))) -> FALSE | BG48: =IF(S48=$BG$39,X48,IF(AA48=$BG$39,AF48,IF(AI48=$BG$39,AN48,IF(AQ48=$BG$39,AV48)))) -> FALSE | BH48: =IF(S48=$BH$39,X48,IF(AA48=$BH$39,AF48,IF(AI48=$BH$39,AN48,IF(AQ48=$BH$39,AV48)))) -> FALSE | BI48: =IF(S48=$BI$39,X48,IF(AA48=$BI$39,AF48,IF(AI48=$BI$39,AN48,IF(AQ48=$BI$39,AV48)))) -> FALSE | BJ48: =IF(S48=$BJ$39,X48,IF(AA48=$BJ$39,AF48,IF(AI48=$BJ$39,AN48,IF(AQ48=$BJ$39,AV48)))) -> 0.30805781 | BK48: =IF(S48=$BK$39,X48,IF(AA48=$BK$39,AF48,IF(AI48=$BK$39,AN48,IF(AQ48=$BK$39,AV48)))) -> 0.30805781 | BL48: =IF(S48=$BL$39,X48,IF(AA48=$BL$39,AF48,IF(AI48=$BL$39,AN48,IF(AQ48=$BL$39,AV48)))) -> FALSE | BM48: =IF(S48=$BM$39,X48,IF(AA48=$BM$39,AF48,IF(AI48=$BM$39,AN48,IF(AQ48=$BM$39,AV48)))) -> 3.0805781 | BN48: =IF(S48=$BN$39,X48,IF(AA48=$BN$39,AF48,IF(AI48=$BN$39,AN48,IF(AQ48=$BN$39,AV48)))) -> FALSE | BO48: =IF(S48=$BO$39,X48,IF(AA48=$BO$39,AF48,IF(AI48=$BO$39,AN48,IF(AQ48=$BO$39,AV48)))) -> FALSE | BP48: =IF(S48=$BP$39,X48,IF(AA48=$BP$39,AF48,IF(AI48=$BP$39,AN48,IF(AQ48=$BP$39,AV48)))) -> FALSE | BQ48: =IF(S48=$BQ$39,X48,IF(AA48=$BQ$39,AF48,IF(AI48=$BQ$39,AN48,IF(AQ48=$BQ$39,AV48)))) -> FALSE | BR48: =IF(S48=$BR$39,X48,IF(AA48=$BR$39,AF48,IF(AI48=$BR$39,AN48,IF(AQ48=$BR$39,AV48)))) -> FALSE
A49: Latex | B49: Latex Experto y Homologos | C49: L. Experto | D49: Galon | E49: - | F49: - | G49: Verde Pistacho | H49: 212 | I49: 219 | J49: 115 | P49: Intensa | Q49: 120 | R49: =IF(P49=$A$32,$G$32,IF(P49=$A$33,$G$33,IF(P49=$A$34,$G$34,IF(P49=$A$35,$G$35)))) -> 0 | S49: AV | U49: 153.5 | V49: =(T49*48)+(U49) -> 153.5 | W49: =(V49/48) -> 3.1979167 | X49: =(W49/0.033814) -> 94.573747 | Y49: =(X49*0.03) -> 2.8372124 | Z49: =IF(S49="",0,VLOOKUP(S49,[1]!Costo_Twist,2,FALSE)*W49) -> 588.11708 | AA49: VE | AC49: 2.5 | AD49: =(AB49*48)+(AC49) -> 2.5 | AE49: =(AD49/48) -> 0.052083333 | AF49: =(AE49/0.033814) -> 1.540289 | AG49: =(AF49*0.03) -> 0.046208671 | AH49: =IF(AA49="",0,VLOOKUP(AA49,[1]!Costo_Twist,2,FALSE)*AE49) -> 6.2248031 | AI49: NE | AK49: 6 | AL49: =(AJ49*48)+(AK49) -> 6 | AM49: =(AL49/48) -> 0.125 | AN49: =(AM49/0.033814) -> 3.6966937 | AO49: =(AN49*0.03) -> 0.11090081 | AP49: =IF(AI49="",0,VLOOKUP(AI49,[1]!Costo_Twist,2,FALSE)*AM49) -> 15.520744 | AT49: =(AR49*48)+(AS49) -> 0 | AU49: =(AT49/48) -> 0 | AV49: =(AU49/0.033814) -> 0 | AW49: =(AV49*0.03) -> 0 | AX49: =IF(AQ49="",0,VLOOKUP(AQ49,[1]!Costo_Twist,2,FALSE)*AU49) -> 0 | AY49: =(Z49+AH49+AP49+AX49) -> 609.86263 | AZ49: =(W49+AE49+AM49+AU49) -> 3.375 | BA49: =(Q49+AZ49) -> 123.375 | BB49: =IF(BA49>=133,"sobrellenado","ok") -> ok | BC49: =IF((COUNTIF($AA49,$S49)+COUNTIF($AI49,$S49)+COUNTIF($AQ49,$S49)+COUNTIF($S49,$AA49)+COUNTIF($AI49,$AA49)+COUNTIF($AQ49,$AA49)+COUNTIF($S49,$AI49)+COUNTIF($AA49,$AI49)+COUNTIF($AQ49,$AI49)+COUNTIF($S49,$AQ49)+COUNTIF($AA49,$AQ49)+COUNTIF($AI49,$AQ49))>1,"Falla","ok") -> ok | BE49: =IF(S49=$BE$39,X49,IF(AA49=$BE$39,AF49,IF(AI49=$BE$39,AN49,IF(AQ49=$BE$39,AV49)))) -> FALSE | BF49: =IF(S49=$BF$39,X49,IF(AA49=$BF$39,AF49,IF(AI49=$BF$39,AN49,IF(AQ49=$BF$39,AV49)))) -> FALSE | BG49: =IF(S49=$BG$39,X49,IF(AA49=$BG$39,AF49,IF(AI49=$BG$39,AN49,IF(AQ49=$BG$39,AV49)))) -> 94.573747 | BH49: =IF(S49=$BH$39,X49,IF(AA49=$BH$39,AF49,IF(AI49=$BH$39,AN49,IF(AQ49=$BH$39,AV49)))) -> FALSE | BI49: =IF(S49=$BI$39,X49,IF(AA49=$BI$39,AF49,IF(AI49=$BI$39,AN49,IF(AQ49=$BI$39,AV49)))) -> FALSE | BJ49: =IF(S49=$BJ$39,X49,IF(AA49=$BJ$39,AF49,IF(AI49=$BJ$39,AN49,IF(AQ49=$BJ$39,AV49)))) -> FALSE | BK49: =IF(S49=$BK$39,X49,IF(AA49=$BK$39,AF49,IF(AI49=$BK$39,AN49,IF(AQ49=$BK$39,AV49)))) -> FALSE | BL49: =IF(S49=$BL$39,X49,IF(AA49=$BL$39,AF49,IF(AI49=$BL$39,AN49,IF(AQ49=$BL$39,AV49)))) -> 3.6966937 | BM49: =IF(S49=$BM$39,X49,IF(AA49=$BM$39,AF49,IF(AI49=$BM$39,AN49,IF(AQ49=$BM$39,AV49)))) -> FALSE | BN49: =IF(S49=$BN$39,X49,IF(AA49=$BN$39,AF49,IF(AI49=$BN$39,AN49,IF(AQ49=$BN$39,AV49)))) -> FALSE | BO49: =IF(S49=$BO$39,X49,IF(AA49=$BO$39,AF49,IF(AI49=$BO$39,AN49,IF(AQ49=$BO$39,AV49)))) -> FALSE | BP49: =IF(S49=$BP$39,X49,IF(AA49=$BP$39,AF49,IF(AI49=$BP$39,AN49,IF(AQ49=$BP$39,AV49)))) -> FALSE | BQ49: =IF(S49=$BQ$39,X49,IF(AA49=$BQ$39,AF49,IF(AI49=$BQ$39,AN49,IF(AQ49=$BQ$39,AV49)))) -> 1.540289 | BR49: =IF(S49=$BR$39,X49,IF(AA49=$BR$39,AF49,IF(AI49=$BR$39,AN49,IF(AQ49=$BR$39,AV49)))) -> FALSE
A50: Latex | B50: Latex Experto y Homologos | C50: L. Experto | D50: Galon | E50: - | F50: - | G50: Verde Musgo | H50: 127 | I50: 142 | J50: 99 | P50: Intensa | Q50: 120 | R50: =IF(P50=$A$32,$G$32,IF(P50=$A$33,$G$33,IF(P50=$A$34,$G$34,IF(P50=$A$35,$G$35)))) -> 0 | S50: OC | U50: 145 | V50: =(T50*48)+(U50) -> 145 | W50: =(V50/48) -> 3.0208333 | X50: =(W50/0.033814) -> 89.336764 | Y50: =(X50*0.03) -> 2.6801029 | Z50: =IF(S50="",0,VLOOKUP(S50,[1]!Costo_Twist,2,FALSE)*W50) -> 442.3171 | AA50: NE | AC50: 58 | AD50: =(AB50*48)+(AC50) -> 58 | AE50: =(AD50/48) -> 1.2083333 | AF50: =(AE50/0.033814) -> 35.734706 | AG50: =(AF50*0.03) -> 1.0720412 | AH50: =IF(AA50="",0,VLOOKUP(AA50,[1]!Costo_Twist,2,FALSE)*AE50) -> 150.03386 | AI50: VE | AK50: 35.5 | AL50: =(AJ50*48)+(AK50) -> 35.5 | AM50: =(AL50/48) -> 0.73958333 | AN50: =(AM50/0.033814) -> 21.872104 | AO50: =(AN50*0.03) -> 0.65616313 | AP50: =IF(AI50="",0,VLOOKUP(AI50,[1]!Costo_Twist,2,FALSE)*AM50) -> 88.392204 | AT50: =(AR50*48)+(AS50) -> 0 | AU50: =(AT50/48) -> 0 | AV50: =(AU50/0.033814) -> 0 | AW50: =(AV50*0.03) -> 0 | AX50: =IF(AQ50="",0,VLOOKUP(AQ50,[1]!Costo_Twist,2,FALSE)*AU50) -> 0 | AY50: =(Z50+AH50+AP50+AX50) -> 680.74317 | AZ50: =(W50+AE50+AM50+AU50) -> 4.96875 | BA50: =(Q50+AZ50) -> 124.96875 | BB50: =IF(BA50>=133,"sobrellenado","ok") -> ok | BC50: =IF((COUNTIF($AA50,$S50)+COUNTIF($AI50,$S50)+COUNTIF($AQ50,$S50)+COUNTIF($S50,$AA50)+COUNTIF($AI50,$AA50)+COUNTIF($AQ50,$AA50)+COUNTIF($S50,$AI50)+COUNTIF($AA50,$AI50)+COUNTIF($AQ50,$AI50)+COUNTIF($S50,$AQ50)+COUNTIF($AA50,$AQ50)+COUNTIF($AI50,$AQ50))>1,"Falla","ok") -> ok | BE50: =IF(S50=$BE$39,X50,IF(AA50=$BE$39,AF50,IF(AI50=$BE$39,AN50,IF(AQ50=$BE$39,AV50)))) -> FALSE | BF50: =IF(S50=$BF$39,X50,IF(AA50=$BF$39,AF50,IF(AI50=$BF$39,AN50,IF(AQ50=$BF$39,AV50)))) -> FALSE | BG50: =IF(S50=$BG$39,X50,IF(AA50=$BG$39,AF50,IF(AI50=$BG$39,AN50,IF(AQ50=$BG$39,AV50)))) -> FALSE | BH50: =IF(S50=$BH$39,X50,IF(AA50=$BH$39,AF50,IF(AI50=$BH$39,AN50,IF(AQ50=$BH$39,AV50)))) -> FALSE | BI50: =IF(S50=$BI$39,X50,IF(AA50=$BI$39,AF50,IF(AI50=$BI$39,AN50,IF(AQ50=$BI$39,AV50)))) -> FALSE | BJ50: =IF(S50=$BJ$39,X50,IF(AA50=$BJ$39,AF50,IF(AI50=$BJ$39,AN50,IF(AQ50=$BJ$39,AV50)))) -> FALSE | BK50: =IF(S50=$BK$39,X50,IF(AA50=$BK$39,AF50,IF(AI50=$BK$39,AN50,IF(AQ50=$BK$39,AV50)))) -> FALSE | BL50: =IF(S50=$BL$39,X50,IF(AA50=$BL$39,AF50,IF(AI50=$BL$39,AN50,IF(AQ50=$BL$39,AV50)))) -> 35.734706 | BM50: =IF(S50=$BM$39,X50,IF(AA50=$BM$39,AF50,IF(AI50=$BM$39,AN50,IF(AQ50=$BM$39,AV50)))) -> 89.336764 | BN50: =IF(S50=$BN$39,X50,IF(AA50=$BN$39,AF50,IF(AI50=$BN$39,AN50,IF(AQ50=$BN$39,AV50)))) -> FALSE | BO50: =IF(S50=$BO$39,X50,IF(AA50=$BO$39,AF50,IF(AI50=$BO$39,AN50,IF(AQ50=$BO$39,AV50)))) -> FALSE | BP50: =IF(S50=$BP$39,X50,IF(AA50=$BP$39,AF50,IF(AI50=$BP$39,AN50,IF(AQ50=$BP$39,AV50)))) -> FALSE | BQ50: =IF(S50=$BQ$39,X50,IF(AA50=$BQ$39,AF50,IF(AI50=$BQ$39,AN50,IF(AQ50=$BQ$39,AV50)))) -> 21.872104 | BR50: =IF(S50=$BR$39,X50,IF(AA50=$BR$39,AF50,IF(AI50=$BR$39,AN50,IF(AQ50=$BR$39,AV50)))) -> FALSE
A51: Latex | B51: Latex Experto y Homologos | C51: L. Experto | D51: Galon | E51: - | F51: - | G51: Rosa Viejo | H51: 237 | I51: 201 | J51: 205 | P51: Media | Q51: 124 | R51: =IF(P51=$A$32,$G$32,IF(P51=$A$33,$G$33,IF(P51=$A$34,$G$34,IF(P51=$A$35,$G$35)))) -> 0 | S51: MA | U51: 11.5 | V51: =(T51*48)+(U51) -> 11.5 | W51: =(V51/48) -> 0.23958333 | X51: =(W51/0.033814) -> 7.0853295 | Y51: =(X51*0.03) -> 0.21255989 | Z51: =IF(S51="",0,VLOOKUP(S51,[1]!Costo_Twist,2,FALSE)*W51) -> 69.599394 | AA51: NE | AC51: 6.5 | AD51: =(AB51*48)+(AC51) -> 6.5 | AE51: =(AD51/48) -> 0.13541667 | AF51: =(AE51/0.033814) -> 4.0047515 | AG51: =(AF51*0.03) -> 0.12014254 | AH51: =IF(AA51="",0,VLOOKUP(AA51,[1]!Costo_Twist,2,FALSE)*AE51) -> 16.814139 | AI51: RO | AK51: 5 | AL51: =(AJ51*48)+(AK51) -> 5 | AM51: =(AL51/48) -> 0.10416667 | AN51: =(AM51/0.033814) -> 3.0805781 | AO51: =(AN51*0.03) -> 0.092417342 | AP51: =IF(AI51="",0,VLOOKUP(AI51,[1]!Costo_Twist,2,FALSE)*AM51) -> 26.11199 | AT51: =(AR51*48)+(AS51) -> 0 | AU51: =(AT51/48) -> 0 | AV51: =(AU51/0.033814) -> 0 | AW51: =(AV51*0.03) -> 0 | AX51: =IF(AQ51="",0,VLOOKUP(AQ51,[1]!Costo_Twist,2,FALSE)*AU51) -> 0 | AY51: =(Z51+AH51+AP51+AX51) -> 112.52552 | AZ51: =(W51+AE51+AM51+AU51) -> 0.47916667 | BA51: =(Q51+AZ51) -> 124.47917 | BB51: =IF(BA51>=133,"sobrellenado","ok") -> ok | BC51: =IF((COUNTIF($AA51,$S51)+COUNTIF($AI51,$S51)+COUNTIF($AQ51,$S51)+COUNTIF($S51,$AA51)+COUNTIF($AI51,$AA51)+COUNTIF($AQ51,$AA51)+COUNTIF($S51,$AI51)+COUNTIF($AA51,$AI51)+COUNTIF($AQ51,$AI51)+COUNTIF($S51,$AQ51)+COUNTIF($AA51,$AQ51)+COUNTIF($AI51,$AQ51))>1,"Falla","ok") -> ok | BE51: =IF(S51=$BE$39,X51,IF(AA51=$BE$39,AF51,IF(AI51=$BE$39,AN51,IF(AQ51=$BE$39,AV51)))) -> FALSE | BF51: =IF(S51=$BF$39,X51,IF(AA51=$BF$39,AF51,IF(AI51=$BF$39,AN51,IF(AQ51=$BF$39,AV51)))) -> FALSE | BG51: =IF(S51=$BG$39,X51,IF(AA51=$BG$39,AF51,IF(AI51=$BG$39,AN51,IF(AQ51=$BG$39,AV51)))) -> FALSE | BH51: =IF(S51=$BH$39,X51,IF(AA51=$BH$39,AF51,IF(AI51=$BH$39,AN51,IF(AQ51=$BH$39,AV51)))) -> FALSE | BI51: =IF(S51=$BI$39,X51,IF(AA51=$BI$39,AF51,IF(AI51=$BI$39,AN51,IF(AQ51=$BI$39,AV51)))) -> FALSE | BJ51: =IF(S51=$BJ$39,X51,IF(AA51=$BJ$39,AF51,IF(AI51=$BJ$39,AN51,IF(AQ51=$BJ$39,AV51)))) -> FALSE | BK51: =IF(S51=$BK$39,X51,IF(AA51=$BK$39,AF51,IF(AI51=$BK$39,AN51,IF(AQ51=$BK$39,AV51)))) -> 7.0853295 | BL51: =IF(S51=$BL$39,X51,IF(AA51=$BL$39,AF51,IF(AI51=$BL$39,AN51,IF(AQ51=$BL$39,AV51)))) -> 4.0047515 | BM51: =IF(S51=$BM$39,X51,IF(AA51=$BM$39,AF51,IF(AI51=$BM$39,AN51,IF(AQ51=$BM$39,AV51)))) -> FALSE | BN51: =IF(S51=$BN$39,X51,IF(AA51=$BN$39,AF51,IF(AI51=$BN$39,AN51,IF(AQ51=$BN$39,AV51)))) -> FALSE | BO51: =IF(S51=$BO$39,X51,IF(AA51=$BO$39,AF51,IF(AI51=$BO$39,AN51,IF(AQ51=$BO$39,AV51)))) -> 3.0805781 | BP51: =IF(S51=$BP$39,X51,IF(AA51=$BP$39,AF51,IF(AI51=$BP$39,AN51,IF(AQ51=$BP$39,AV51)))) -> FALSE | BQ51: =IF(S51=$BQ$39,X51,IF(AA51=$BQ$39,AF51,IF(AI51=$BQ$39,AN51,IF(AQ51=$BQ$39,AV51)))) -> FALSE | BR51: =IF(S51=$BR$39,X51,IF(AA51=$BR$39,AF51,IF(AI51=$BR$39,AN51,IF(AQ51=$BR$39,AV51)))) -> FALSE
...

Sheet Control de Cambios
A1: ULTIMA MODIFICACION | B1: COLOR | C1: CARTILLA | D1: DOCUMENTO | E1: RESPONSABLE | F1: FORMULA ANTERIOR
A2: 20.06.19 | D2: Se Homologa a este formulario Latex CK70 Plus | E2: KS
A3: 11.08.20 | B3: 8723M | C3: MILLENNIUM | D3: SGI-4133 | E3: FSB
A4: 14.02.23 | B4: 63W | C4: MILLENNIUM | D4: SGI-5374 | E4: KS | F4: BB AZ-0,5 OC-2,5

Sheet Calculos
A1: COSTO COLORANTES
A3: CARTILLA | B3: (Todas)
A5: Etiquetas de fila | B5: Promedio | C5: minimo | D5: Maximo | E5: Des. Std
A6: Base N | B6: 1306.408 | C6: 351.19728 | D6: 2498.0036 | E6: 350.65446
A7: Base P | B7: 228.58916 | C7: 15.679768 | D7: 753.97809 | E7: 138.48098
A8: Base U | B8: 369.37258 | C8: 46.508505 | D8: 1290.0487 | E8: 205.53705
A9: Base W | B9: 72.561432 | C9: 1.8750739 | D9: 1808.2386 | E9: 79.765873
A10: Total general | B10: 405.94799 | C10: 1.8750739 | D10: 2498.0036 | E10: 496.88466
A16: CONSUMO COLORANTES
A18: CARTILLA | B18: (Todas)
A20: Etiquetas de fila | B20: Promedio | C20: minimo | D20: Maximo | E20: Des. Std
A21: Base N | B21: 11.953573 | C21: 3.2708333 | D21: 15.958333 | E21: 1.0339638
A22: Base P | B22: 1.995478 | C22: 0.20833333 | D22: 9.4270833 | E22: 1.1521169
A23: Base U | B23: 3.2154826 | C23: 0.66666667 | D23: 13.854167 | E23: 1.5924289
A24: Base W | B24: 0.60161711 | C24: 0.03125 | D24: 12 | E24: 0.65008819
A25: Total general | B25: 3.6372004 | C25: 0.03125 | D25: 15.958333 | E25: 4.3384061

Sheet Formulario para Alfa Tinting
A1: code | B1: description | C1: short_description | D1: r | E1: g | F1: b | G1: gravimetric | H1: size | I1: b2 | J1: b4 | K1: F7101 | L1: F7103 | M1: AO | N1: AT | O1: AV | P1: AZ | Q1: BC | R1: CA | S1: MA | T1: NE | U1: OC | V1: RJ | W1: RO | X1: RT | Y1: VE | Z1: VI
A2: =_xlfn.CONCAT('FORMULARIO '!G40,'FORMULARIO '!E40,'FORMULARIO '!B40,'FORMULARIO '!E40,'FORMULARIO '!C40,'FORMULARIO '!E40,'FORMULARIO '!P40) -> Marfil -Latex Experto y Homologos-L. Experto -Blanca | B2: =(A2) -> Marfil -Latex Experto y Homologos-L. Experto -Blanca | C2: =('FORMULARIO '!G40) -> Marfil | D2: =('FORMULARIO '!H40) -> 0 | E2: =('FORMULARIO '!I40) -> 0 | F2: =('FORMULARIO '!J40) -> 0 | G2: 0 | H2: 3785 | M2: =('FORMULARIO '!BE40) -> FALSE | N2: =('FORMULARIO '!BF40) -> FALSE | O2: =('FORMULARIO '!BG40) -> 4.3128093 | P2: =('FORMULARIO '!BH40) -> FALSE | Q2: =('FORMULARIO '!BI40) -> FALSE | R2: =('FORMULARIO '!BJ40) -> 0.30805781 | S2: =('FORMULARIO '!BK40) -> FALSE | T2: =('FORMULARIO '!BL40) -> FALSE | ... Z2: =('FORMULARIO '!BR40) -> FALSE
A3: =_xlfn.CONCAT('FORMULARIO '!G41,'FORMULARIO '!E41,'FORMULARIO '!B41,'FORMULARIO '!E41,'FORMULARIO '!C41,'FORMULARIO '!E41,'FORMULARIO '!P41) -> Blanco Ingles -Latex Experto y Homologos-L. Experto -Blanca | B3: =(A3) -> Blanco Ingles -Latex Experto y Homologos-L. Experto -Blanca | C3: =('FORMULARIO '!G41) -> Blanco Ingles | D3: =('FORMULARIO '!H41) -> 246 | E3: =('FORMULARIO '!I41) -> 240 | F3: =('FORMULARIO '!J41) -> 228 | G3: 0 | H3: 3785 | M3: =('FORMULARIO '!BE41) -> FALSE | N3: =('FORMULARIO '!BF41) -> FALSE | O3: =('FORMULARIO '!BG41) -> 2.7725203 | P3: =('FORMULARIO '!BH41) -> FALSE | Q3: =('FORMULARIO '!BI41) -> FALSE | R3: =('FORMULARIO '!BJ41) -> FALSE | S3: =('FORMULARIO '!BK41) -> FALSE | T3: =('FORMULARIO '!BL41) -> 1.540289 | ... Z3: =('FORMULARIO '!BR41) -> FALSE
A4: =_xlfn.CONCAT('FORMULARIO '!G42,'FORMULARIO '!E42,'FORMULARIO '!B42,'FORMULARIO '!E42,'FORMULARIO '!C42,'FORMULARIO '!E42,'FORMULARIO '!P42) -> Damasco-Latex Experto y Homologos-L. Experto -Blanca | B4: =(A4) -> Damasco-Latex Experto y Homologos-L. Experto -Blanca | C4: =('FORMULARIO '!G42) -> Damasco | D4: =('FORMULARIO '!H42) -> 252 | E4: =('FORMULARIO '!I42) -> 220 | F4: =('FORMULARIO '!J42) -> 179 | G4: 0 | H4: 3785 | M4: =('FORMULARIO '!BE42) -> FALSE | N4: =('FORMULARIO '!BF42) -> FALSE | O4: =('FORMULARIO '!BG42) -> FALSE | P4: =('FORMULARIO '!BH42) -> FALSE | Q4: =('FORMULARIO '!BI42) -> FALSE | R4: =('FORMULARIO '!BJ42) -> 1.8483468 | S4: =('FORMULARIO '!BK42) -> FALSE | T4: =('FORMULARIO '!BL42) -> FALSE | ... Z4: =('FORMULARIO '!BR42) -> FALSE
A5: =_xlfn.CONCAT('FORMULARIO '!G43,'FORMULARIO '!E43,'FORMULARIO '!B43,'FORMULARIO '!E43,'FORMULARIO '!C43,'FORMULARIO '!E43,'FORMULARIO '!P43) -> Ocre -Latex Experto y Homologos-L. Experto -Media | B5: =(A5) -> Ocre -Latex Experto y Homologos-L. Experto -Media | C5: =('FORMULARIO '!G43) -> Ocre | D5: =('FORMULARIO '!H43) -> 254 | E5: =('FORMULARIO '!I43) -> 219 | F5: =('FORMULARIO '!J43) -> 137 | G5: 0 | H5: 3785 | M5: =('FORMULARIO '!BE43) -> FALSE | N5: =('FORMULARIO '!BF43) -> FALSE | O5: =('FORMULARIO '!BG43) -> 73.317758 | P5: =('FORMULARIO '!BH43) -> FALSE | Q5: =('FORMULARIO '!BI43) -> FALSE | R5: =('FORMULARIO '!BJ43) -> FALSE | S5: =('FORMULARIO '!BK43) -> FALSE | T5: =('FORMULARIO '!BL43) -> FALSE | ... Z5: =('FORMULARIO '!BR43) -> FALSE
A6: =_xlfn.CONCAT('FORMULARIO '!G44,'FORMULARIO '!E44,'FORMULARIO '!B44,'FORMULARIO '!E44,'FORMULARIO '!C44,'FORMULARIO '!E44,'FORMULARIO '!P44) -> Crema-Latex Experto y Homologos-L. Experto -Blanca | B6: =(A6) -> Crema-Latex Experto y Homologos-L. Experto -Blanca | C6: =('FORMULARIO '!G44) -> Crema | D6: =('FORMULARIO '!H44) -> 248 | E6: =('FORMULARIO '!I44) -> 233 | F6: =('FORMULARIO '!J44) -> 192 | G6: 0 | H6: 3785 | M6: =('FORMULARIO '!BE44) -> FALSE | N6: =('FORMULARIO '!BF44) -> FALSE | O6: =('FORMULARIO '!BG44) -> FALSE | P6: =('FORMULARIO '!BH44) -> FALSE | Q6: =('FORMULARIO '!BI44) -> FALSE | R6: =('FORMULARIO '!BJ44) -> FALSE | S6: =('FORMULARIO '!BK44) -> FALSE | T6: =('FORMULARIO '!BL44) -> 1.2322312 | ... Z6: =('FORMULARIO '!BR44) -> FALSE
A7: =_xlfn.CONCAT('FORMULARIO '!G45,'FORMULARIO '!E45,'FORMULARIO '!B45,'FORMULARIO '!E45,'FORMULARIO '!C45,'FORMULARIO '!E45,'FORMULARIO '!P45) -> Celeste Cielo-Latex Experto y Homologos-L. Experto -Blanca | B7: =(A7) -> Celeste Cielo-Latex Experto y Homologos-L. Experto -Blanca | C7: =('FORMULARIO '!G45) -> Celeste Cielo | D7: =('FORMULARIO '!H45) -> 198 | E7: =('FORMULARIO '!I45) -> 230 | F7: =('FORMULARIO '!J45) -> 245 | G7: 0 | H7: 3785 | M7: =('FORMULARIO '!BE45) -> FALSE | N7: =('FORMULARIO '!BF45) -> FALSE | O7: =('FORMULARIO '!BG45) -> FALSE | P7: =('FORMULARIO '!BH45) -> 4.9289249 | Q7: =('FORMULARIO '!BI45) -> FALSE | R7: =('FORMULARIO '!BJ45) -> 0.30805781 | S7: =('FORMULARIO '!BK45) -> FALSE | T7: =('FORMULARIO '!BL45) -> 0.61611561 | ... Z7: =('FORMULARIO '!BR45) -> FALSE
A8: =_xlfn.CONCAT('FORMULARIO '!G46,'FORMULARIO '!E46,'FORMULARIO '!B46,'FORMULARIO '!E46,'FORMULARIO '!C46,'FORMULARIO '!E46,'FORMULARIO '!P46) -> Blanco Invierno-Latex Experto y Homologos-L. Experto -Blanca | B8: =(A8) -> Blanco Invierno-Latex Experto y Homologos-L. Experto -Blanca | C8: =('FORMULARIO '!G46) -> Blanco Invierno | D8: =('FORMULARIO '!H46) -> 239 | E8: =('FORMULARIO '!I46) -> 242 | F8: =('FORMULARIO '!J46) -> 235 | G8: 0 | H8: 3785 | M8: =('FORMULARIO '!BE46) -> FALSE | N8: =('FORMULARIO '!BF46) -> FALSE | O8: =('FORMULARIO '!BG46) -> FALSE | P8: =('FORMULARIO '!BH46) -> FALSE | Q8: =('FORMULARIO '!BI46) -> FALSE | R8: =('FORMULARIO '!BJ46) -> 2.4644625 | S8: =('FORMULARIO '!BK46) -> FALSE | T8: =('FORMULARIO '!BL46) -> 1.8483468 | ... Z8: =('FORMULARIO '!BR46) -> FALSE
A9: =_xlfn.CONCAT('FORMULARIO '!G47,'FORMULARIO '!E47,'FORMULARIO '!B47,'FORMULARIO '!E47,'FORMULARIO '!C47,'FORMULARIO '!E47,'FORMULARIO '!P47) -> Rojo Colonial N-Latex Experto y Homologos-L. Experto -Intensa | B9: =(A9) -> Rojo Colonial N-Latex Experto y Homologos-L. Experto -Intensa | C9: =('FORMULARIO '!G47) -> Rojo Colonial N | D9: =('FORMULARIO '!H47) -> 185 | E9: =('FORMULARIO '!I47) -> 79 | F9: =('FORMULARIO '!J47) -> 66 | G9: 0 | H9: 3785 | M9: =('FORMULARIO '!BE47) -> FALSE | N9: =('FORMULARIO '!BF47) -> FALSE | O9: =('FORMULARIO '!BG47) -> FALSE | P9: =('FORMULARIO '!BH47) -> FALSE | Q9: =('FORMULARIO '!BI47) -> FALSE | R9: =('FORMULARIO '!BJ47) -> FALSE | S9: =('FORMULARIO '!BK47) -> 75.474163 | T9: =('FORMULARIO '!BL47) -> 14.478717 | ... Z9: =('FORMULARIO '!BR47) -> FALSE
A10: =_xlfn.CONCAT('FORMULARIO '!G48,'FORMULARIO '!E48,'FORMULARIO '!B48,'FORMULARIO '!E48,'FORMULARIO '!C48,'FORMULARIO '!E48,'FORMULARIO '!P48) -> Marfil Oriental-Latex Experto y Homologos-L. Experto -Blanca | B10: =(A10) -> Marfil Oriental-Latex Experto y Homologos-L. Experto -Blanca | C10: =('FORMULARIO '!G48) -> Marfil Oriental | D10: =('FORMULARIO '!H48) -> 253 | E10: =('FORMULARIO '!I48) -> 247 | F10: =('FORMULARIO '!J48) -> 225 | G10: 0 | H10: 3785 | M10: =('FORMULARIO '!BE48) -> FALSE | N10: =('FORMULARIO '!BF48) -> FALSE | O10: =('FORMULARIO '!BG48) -> FALSE | P10: =('FORMULARIO '!BH48) -> FALSE | Q10: =('FORMULARIO '!BI48) -> FALSE | R10: =('FORMULARIO '!BJ48) -> 0.30805781 | S10: =('FORMULARIO '!BK48) -> 0.30805781 | T10: =('FORMULARIO '!BL48) -> FALSE | ... Z10: =('FORMULARIO '!BR48) -> FALSE
A11: =_xlfn.CONCAT('FORMULARIO '!G49,'FORMULARIO '!E49,'FORMULARIO '!B49,'FORMULARIO '!E49,'FORMULARIO '!C49,'FORMULARIO '!E49,'FORMULARIO '!P49) -> Verde Pistacho-Latex Experto y Homologos-L. Experto -Intensa | B11: =(A11) -> Verde Pistacho-Latex Experto y Homologos-L. Experto -Intensa | C11: =('FORMULARIO '!G49) -> Verde Pistacho | D11: =('FORMULARIO '!H49) -> 212 | E11: =('FORMULARIO '!I49) -> 219 | F11: =('FORMULARIO '!J49) -> 115 | G11: 0 | H11: 3785 | M11: =('FORMULARIO '!BE49) -> FALSE | N11: =('FORMULARIO '!BF49) -> FALSE | O11: =('FORMULARIO '!BG49) -> 94.573747 | P11: =('FORMULARIO '!BH49) -> FALSE | Q11: =('FORMULARIO '!BI49) -> FALSE | R11: =('FORMULARIO '!BJ49) -> FALSE | S11: =('FORMULARIO '!BK49) -> FALSE | T11: =('FORMULARIO '!BL49) -> 3.6966937 | ... Z11: =('FORMULARIO '!BR49) -> FALSE
A12: =_xlfn.CONCAT('FORMULARIO '!G50,'FORMULARIO '!E50,'FORMULARIO '!B50,'FORMULARIO '!E50,'FORMULARIO '!C50,'FORMULARIO '!E50,'FORMULARIO '!P50) -> Verde Musgo-Latex Experto y Homologos-L. Experto -Intensa | B12: =(A12) -> Verde Musgo-Latex Experto y Homologos-L. Experto -Intensa | C12: =('FORMULARIO '!G50) -> Verde Musgo | D12: =('FORMULARIO '!H50) -> 127 | E12: =('FORMULARIO '!I50) -> 142 | F12: =('FORMULARIO '!J50) -> 99 | G12: 0 | H12: 3785 | M12: =('FORMULARIO '!BE50) -> FALSE | N12: =('FORMULARIO '!BF50) -> FALSE | O12: =('FORMULARIO '!BG50) -> FALSE | P12: =('FORMULARIO '!BH50) -> FALSE | Q12: =('FORMULARIO '!BI50) -> FALSE | R12: =('FORMULARIO '!BJ50) -> FALSE | S12: =('FORMULARIO '!BK50) -> FALSE | T12: =('FORMULARIO '!BL50) -> 35.734706 | ... Z12: =('FORMULARIO '!BR50) -> FALSE
A13: =_xlfn.CONCAT('FORMULARIO '!G51,'FORMULARIO '!E51,'FORMULARIO '!B51,'FORMULARIO '!E51,'FORMULARIO '!C51,'FORMULARIO '!E51,'FORMULARIO '!P51) -> Rosa Viejo-Latex Experto y Homologos-L. Experto -Media | B13: =(A13) -> Rosa Viejo-Latex Experto y Homologos-L. Experto -Media | C13: =('FORMULARIO '!G51) -> Rosa Viejo | D13: =('FORMULARIO '!H51) -> 237 | E13: =('FORMULARIO '!I51) -> 201 | F13: =('FORMULARIO '!J51) -> 205 | G13: 0 | H13: 3785 | M13: =('FORMULARIO '!BE51) -> FALSE | N13: =('FORMULARIO '!BF51) -> FALSE | O13: =('FORMULARIO '!BG51) -> FALSE | P13: =('FORMULARIO '!BH51) -> FALSE | Q13: =('FORMULARIO '!BI51) -> FALSE | R13: =('FORMULARIO '!BJ51) -> FALSE | S13: =('FORMULARIO '!BK51) -> 7.0853295 | T13: =('FORMULARIO '!BL51) -> 4.0047515 | ... Z13: =('FORMULARIO '!BR51) -> FALSE
... A2311: =_xlfn.CONCAT('FORMULARIO '!G2349,'FORMULARIO '!E2349,'FORMULARIO '!B2349,'FORMULARIO '!E2349,'FORMULARIO '!C2349,'FORMULARIO '!E2349,'FORMULARIO '!P2349) -> 8780-Latex Experto y Homologos-Todocolor-Blanca | B2311: =(A2311) -> 8780-Latex Experto y Homologos-Todocolor-Blanca | C2311: =('FORMULARIO '!G2349) -> 8780 | D2311: =('FORMULARIO '!H2349) -> 0 | E2311: =('FORMULARIO '!I2349) -> 0 | F2311: =('FORMULARIO '!J2349) -> 0 | G2311: 0 | H2311: 3785 | M2311: =('FORMULARIO '!BE2349) -> FALSE | N2311: =('FORMULARIO '!BF2349) -> FALSE | O2311: =('FORMULARIO '!BG2349) -> FALSE | P2311: =('FORMULARIO '!BH2349) -> FALSE | Q2311: =('FORMULARIO '!BI2349) -> FALSE | R2311: =('FORMULARIO '!BJ2349) -> 7.3933874 | S2311: =('FORMULARIO '!BK2349) -> 1.540289 | T2311: =('FORMULARIO '!BL2349) -> FALSE | ... Z2311: =('FORMULARIO '!BR2349) -> FALSE
A4315: =_xlfn.CONCAT('FORMULARIO '!G4543,'FORMULARIO '!E4543,'FORMULARIO '!B4543,'FORMULARIO '!E4543,'FORMULARIO '!C4543,'FORMULARIO '!E4543,'FORMULARIO '!P4543)
A4316: =_xlfn.CONCAT('FORMULARIO '!G4544,'FORMULARIO '!E4544,'FORMULARIO '!B4544,'FORMULARIO '!E4544,'FORMULARIO '!C4544,'FORMULARIO '!E4544,'FORMULARIO '!P4544)
A4317: =_xlfn.CONCAT('FORMULARIO '!G4545,'FORMULARIO '!E4545,'FORMULARIO '!B4545,'FORMULARIO '!E4545,'FORMULARIO '!C4545,'FORMULARIO '!E4545,'FORMULARIO '!P4545)
A4318: =_xlfn.CONCAT('FORMULARIO '!G4546,'FORMULARIO '!E4546,'FORMULARIO '!B4546,'FORMULARIO '!E4546,'FORMULARIO '!C4546,'FORMULARIO '!E4546,'FORMULARIO '!P4546)
